Workbook
Name Company_Name: FSM!$D$5
Name Company_Name: #REF!
Name Hist_Yr: FSM!#REF!
Name Hist_Yr: #REF!
Name IQ_CH: 110000
Name IQ_CQ: 5000
Name IQ_CY: 10000
Name IQ_DAILY: 500000
Name IQ_FH: 100000
Name IQ_FQ: 500
Name IQ_FY: 1000
Name IQ_LTM: 2000
Name IQ_MONTH: 15000
Name IQ_NTM: 6000
Name IQ_WEEK: 50000
Name IQ_YTD: 3000

Sheet FSM
C2: =Company_Name&" - Financial Statement Model" -> Gourmet Egypt - Financial Statement Model
C3: All amounts are shown in EGP, except per-share data, ratios, and shares outstanding
C5: Company Name | D5: Gourmet Egypt
C6: Ticker | D6: GOUR.CA
C7: Latest Closing Share Price | D7: 17.03
C8: Latest Closing Share Price Date | D8: 46274
C9: Last Historical Year | D9: 46022
C10: Shares outstanding | D10: 400000000
C12: INCOME STATEMENT
C13: Fiscal year | D13: =E13-1 -> 2023 | E13: =F13-1 -> 2024 | F13: =YEAR(D9) -> 2025 | G13: =F13+1 -> 2026 | H13: =G13+1 -> 2027 | I13: =H13+1 -> 2028 | J13: =I13+1 -> 2029 | K13: =J13+1 -> 2030
C14: Fiscal year end date | D14: =EOMONTH(E14,-12) -> 45291 | E14: =EOMONTH(F14,-12) -> 45657 | F14: =D9 -> 46022 | G14: =EOMONTH(F14,12) -> 46387 | H14: =EOMONTH(G14,12) -> 46752 | I14: =EOMONTH(H14,12) -> 47118 | J14: =EOMONTH(I14,12) -> 47483 | K14: =EOMONTH(J14,12) -> 47848
C16: Gross Revenue | D16: 1461003005 | E16: 2117799758 | F16: 2877655973 | G16: =G185 -> 3.5122413e+09 | H16: =H185 -> 4.1456704e+09 | I16: =I185 -> 4.7685376e+09 | J16: =J185 -> 5.3415609e+09 | K16: =K185 -> 5.8763698e+09
C17: Cost of Goods Sold (COGS) | D17: -988835102 | E17: -1426005686 | F17: -1923541960 | G17: =-G16*(1-G39) -> -2.3632735e+09 | H17: =-H16*(1-H39) -> -2.7894875e+09 | I17: =-I16*(1-I39) -> -3.2085947e+09 | J17: =-J16*(1-J39) -> -3.5941635e+09 | K17: =-K16*(1-K39) -> -3.9540191e+09
C18: Gross Profit | D18: =SUM(D16:D17) -> 472167903 | E18: =SUM(E16:E17) -> 691794072 | F18: =SUM(F16:F17) -> 954114013 | G18: =SUM(G16:G17) -> 1.1489678e+09 | H18: =SUM(H16:H17) -> 1.3561829e+09 | I18: =SUM(I16:I17) -> 1.559943e+09 | J18: =SUM(J16:J17) -> 1.7473974e+09 | K18: =SUM(K16:K17) -> 1.9223507e+09
C19: Total Cash Operating Expenses (OpEx) | D19: =D57 -> -312854249 | E19: =E57 -> -405834952 | F19: =F57 -> -592354956 | G19: =G57 -> -6.9158878e+08 | H19: =H57 -> -8.1556945e+08 | I19: =I57 -> -9.3748286e+08 | J19: =J57 -> -1.0496403e+09 | K19: =K57 -> -1.1543181e+09
C20: EBITDA | D20: =SUM(D18:D19) -> 159313654 | E20: =SUM(E18:E19) -> 285959120 | F20: =SUM(F18:F19) -> 361759057 | G20: =SUM(G18:G19) -> 4.5737901e+08 | H20: =SUM(H18:H19) -> 5.4061349e+08 | I20: =SUM(I18:I19) -> 6.224601e+08 | J20: =SUM(J18:J19) -> 6.9775707e+08 | K20: =SUM(K18:K19) -> 7.6803256e+08
C21: Depreciation of Fixed Assets (PPE) | D21: -45088086 | E21: -43207268 | F21: -41355878 | G21: =-G164 -> -35411770 | H21: =-H164 -> -35348965 | I21: =-I164 -> -45672897 | J21: =-J164 -> -56459890 | K21: =-K164 -> -67393060
C22: Amortization of Intangible Assets | D22: -4505081 | E22: -7108381 | F22: -6938280 | G22: =G301 -> -7000000 | H22: =H301 -> -5000000 | I22: =I301 -> -4000000 | J22: =J301 -> -3000000 | K22: =K301 -> -2000000
C23: Amortization of Right-of-Use Assets | D23: -33206271 | E23: -36035425 | F23: -36334900 | G23: =G288 -> -44347531 | H23: =H288 -> -52345562 | I23: =I288 -> -60210233 | J23: =J288 -> -67445546 | K23: =K288 -> -74198345
C24: Total D&A | D24: =SUM(D21:D23) -> -82799438 | E24: =SUM(E21:E23) -> -86351074 | F24: =SUM(F21:F23) -> -84629058 | G24: =SUM(G21:G23) -> -86759301 | H24: =SUM(H21:H23) -> -92694527 | I24: =SUM(I21:I23) -> -1.0988313e+08 | J24: =SUM(J21:J23) -> -1.2690544e+08 | K24: =SUM(K21:K23) -> -1.4359141e+08
C25: Operating Profit (EBIT) | D25: =D20+D24 -> 76514216 | E25: =E20+E24 -> 199608046 | F25: =F20+F24 -> 277129999 | G25: =G20+G24 -> 3.7061971e+08 | H25: =H20+H24 -> 4.4791896e+08 | I25: =I20+I24 -> 5.1257697e+08 | J25: =J20+J24 -> 5.7085163e+08 | K25: =K20+K24 -> 6.2444116e+08
C26: Finance expense | D26: -47950964 | E26: -55620920 | F26: -37780877 | G26: =G241 -> -40228350 | H26: =H241 -> -41822344 | I26: =I241 -> -45435245 | J26: =J241 -> -50173503 | K26: =K241 -> -55196986
C27: Other Income / (Expenses) & Capital Gains | D27: -435610 | E27: 8483341 | F27: 36040096 | G27: =G242 -> 42840526 | H27: =H242 -> 43720738 | I27: =I242 -> 49860748 | J27: =J242 -> 55317613 | K27: =K242 -> 69154501
C28: Profit / (Loss) Before Tax (EBT) | D28: =SUM(D25:D27) -> 28127642 | E28: =SUM(E25:E27) -> 152470467 | F28: =SUM(F25:F27) -> 275389218 | G28: =SUM(G25:G27) -> 3.7323189e+08 | H28: =SUM(H25:H27) -> 4.4981736e+08 | I28: =SUM(I25:I27) -> 5.1700248e+08 | J28: =SUM(J25:J27) -> 5.7599574e+08 | K28: =SUM(K25:K27) -> 6.3839868e+08
C29: Income Tax Expense (Current) | D29: 0 | E29: -22336568 | F29: -69211808 | G29: =G28*-G40 -> -83977175 | H29: =H28*-H40 -> -1.0120891e+08 | I29: =I28*-I40 -> -1.1632556e+08 | J29: =J28*-J40 -> -1.2959904e+08 | K29: =K28*-K40 -> -1.436397e+08
C30: Deferred Tax (Expense) / Benefit | D30: 3617966 | E30: 4907885 | F30: 5035222 | G30: 0 | H30: =G30 -> 0 | I30: =H30 -> 0 | J30: =I30 -> 0 | K30: =J30 -> 0
C31: Net Profit / (Loss) for the Year | D31: =SUM(D28:D30) -> 31745608 | E31: =SUM(E28:E30) -> 135041784 | F31: =SUM(F28:F30) -> 211212632 | G31: =SUM(G28:G30) -> 2.8925471e+08 | H31: =SUM(H28:H30) -> 3.4860845e+08 | I31: =SUM(I28:I30) -> 4.0067692e+08 | J31: =SUM(J28:J30) -> 4.463967e+08 | K31: =SUM(K28:K30) -> 4.9475897e+08
C32: Equity Holders of the Parent Company | D32: =D31-D33 -> 31745161 | E32: =E31-E33 -> 135031718 | F32: =F31-F33 -> 211202869 | G32: =G31-G33 -> 2.8924134e+08 | H32: =H31-H33 -> 3.4859234e+08 | I32: =I31-I33 -> 4.006584e+08 | J32: =J31-J33 -> 4.4637607e+08 | K32: =K31-K33 -> 4.947361e+08
C33: Non-Controlling Interest (NCI) | D33: 447 | E33: 10066 | F33: 9763 | G33: =G257 -> 13370.383 | H33: =H257 -> 16113.924 | I33: =I257 -> 18520.714 | J33: =J257 -> 20634.045 | K33: =K257 -> 22869.522
C35: Normalised EBITDA | D35: =D20-ABS(D49+D50+D51+D52+D56) -> 154063791 | E35: =E20-ABS(E49+E50+E51+E52+E56) -> 278963899 | F35: =F20-ABS(F49+F50+F51+F52+F56) -> 333679968 | G35: =G20-ABS(G49+G50+G51+G52+G56) -> 4.5737901e+08 | H35: =H20-ABS(H49+H50+H51+H52+H56) -> 5.4061349e+08 | I35: =I20-ABS(I49+I50+I51+I52+I56) -> 6.224601e+08 | J35: =J20-ABS(J49+J50+J51+J52+J56) -> 6.9775707e+08 | K35: =K20-ABS(K49+K50+K51+K52+K56) -> 7.6803256e+08
C37: Growth Rates & Margins
C38: Revenue growth | D38: =D16/1098037388-1 -> 0.33055852 | E38: =E16/D16-1 -> 0.44955195 | F38: =F16/E16-1 -> 0.35879512 | G38: =G16/F16-1 -> 0.22052162 | H38: =H16/G16-1 -> 0.18034897 | I38: =I16/H16-1 -> 0.15024523 | J38: =J16/I16-1 -> 0.1201675 | K38: =K16/J16-1 -> 0.10012223
C39: Gross Margin % of Revenue | D39: =D18/D16 -> 0.32318065 | E39: =E18/E16 -> 0.32665698 | F39: =F18/F16 -> 0.33155944 | G39: =AVERAGE(D39:F39) -> 0.32713236 | H39: =G39 -> 0.32713236 | I39: =H39 -> 0.32713236 | J39: =I39 -> 0.32713236 | K39: =J39 -> 0.32713236
C40: Tax rate | E40: =-SUM(E29:E30)/E28 -> 0.11430858 | F40: =-SUM(F29:F30)/F28 -> 0.23303957 | G40: 0.225 | H40: =G40 -> 0.225 | I40: =H40 -> 0.225 | J40: =I40 -> 0.225 | K40: =J40 -> 0.225
C41: Tax payable as % of annual charge | G41: 0.25 | H41: =G41 -> 0.25 | I41: =H41 -> 0.25 | J41: =I41 -> 0.25 | K41: =J41 -> 0.25
C43: OpEx Schedule
C44: Fiscal year | D44: =D$13 -> 2023 | E44: =E$13 -> 2024 | F44: =F$13 -> 2025 | G44: =G$13 -> 2026 | H44: =H$13 -> 2027 | I44: =I$13 -> 2028 | J44: =J$13 -> 2029 | K44: =K$13 -> 2030
C45: Fiscal year end date | D45: =D$14 -> 45291 | E45: =E$14 -> 45657 | F45: =F$14 -> 46022 | G45: =G$14 -> 46387 | H45: =H$14 -> 46752 | I45: =I$14 -> 47118 | J45: =J$14 -> 47483 | K45: =K$14 -> 47848
C47: Selling and Marketing Expenses | D47: -198930816 | E47: -277108013 | F47: -380179028 | G47: =-G$16*G59 -> -4.6727058e+08 | H47: =-H$16*H59 -> -5.5154235e+08 | I47: =-I$16*I59 -> -6.3440895e+08 | J47: =-J$16*J59 -> -7.1064429e+08 | K47: =-K$16*K59 -> -7.8179558e+08
C48: General and Administrative Expenses | D48: -100840540 | E48: -118109354 | F48: -178280004 | G48: =-G$16*G60 -> -2.1863057e+08 | H48: =-H$16*H60 -> -2.5806037e+08 | I48: =-I$16*I60 -> -2.9683271e+08 | J48: =-J$16*J60 -> -3.3250235e+08 | K48: =-K$16*K60 -> -3.6579323e+08
...

Sheet DCF
B2: Discounted Cash Flow Valuation
B3: =FSM!C3 -> All amounts are shown in EGP, except per-share data, ratios, and shares outstanding
B4: Most recent fiscal year end | D4: 46022 | F4: Discount rate (WACC) | H4: =WACC!H78 -> 0.24356206 | I4: Link from WACC
B5: End of first fiscal year | D5: =EOMONTH(D4,12) -> 46387 | F5: Share price (Public Co) | H5: 17.03
B6: Most recent quarter end date | D6: 46022 | F6: Share price date | H6: 46274
B7: Valuation date | D7: 46022 | F7: Implied Share Price | H7: =C72 -> 5.0487907
B8: Portion of First Year Cash Flows | D8: =YEARFRAC(D7,D5) -> 1 | F8: Upside / (Downside) | H8: =H7/H5-1 -> -0.70353548 | I8: {=_xlfn.IFS(H8>15%,"BUY",H8>=0,"HOLD",H8<0,"SELL")} -> SELL
F9: Midyear adjustment? | H9: 0
B10: Unlevered Free Cash Flows
C11: LTM | D11: Actual | E11: Forecasts
B12: Fiscal year ended | C12: =D7 -> 46022 | D12: =D4 -> 46022 | E12: =EOMONTH(D12,12) -> 46387 | F12: =EOMONTH(E12,12) -> 46752 | G12: =EOMONTH(F12,12) -> 47118 | H12: =EOMONTH(G12,12) -> 47483 | I12: =EOMONTH(H12,12) -> 47848
B14: Revenue | C14: =E14*(1-$D$8)+D14*$D$8 -> 2877655973 | D14: =FSM!F16 -> 2877655973 | E14: =FSM!G16 -> 3.5122413e+09 | F14: =FSM!H16 -> 4.1456704e+09 | G14: =FSM!I16 -> 4.7685376e+09 | H14: =FSM!J16 -> 5.3415609e+09 | I14: =FSM!K16 -> 5.8763698e+09
B15: % growth | E15: =E14/D14-1 -> 0.22052162 | F15: =F14/E14-1 -> 0.18034897 | G15: =G14/F14-1 -> 0.15024523 | H15: =H14/G14-1 -> 0.1201675 | I15: =I14/H14-1 -> 0.10012223
B16: EBITDA | C16: =E16*(1-$D$8)+D16*$D$8 -> 333679968 | D16: =FSM!F35 -> 333679968 | E16: =FSM!G35 -> 4.5737901e+08 | F16: =FSM!H35 -> 5.4061349e+08 | G16: =FSM!I35 -> 6.224601e+08 | H16: =FSM!J35 -> 6.9775707e+08 | I16: =FSM!K35 -> 7.6803256e+08
B17: % margin | D17: =D16/D14 -> 0.11595548 | E17: =E16/E14 -> 0.13022426 | F17: =F16/F14 -> 0.13040436 | G17: =G16/G14 -> 0.1305348 | H17: =H16/H14 -> 0.13062794 | I17: =I16/I14 -> 0.13069847
B18: EBIT | C18: =E18*(1-$D$8)+D18*$D$8 -> 277129999 | D18: =FSM!F25 -> 277129999 | E18: =FSM!G25 -> 3.7061971e+08 | F18: =FSM!H25 -> 4.4791896e+08 | G18: =FSM!I25 -> 5.1257697e+08 | H18: =FSM!J25 -> 5.7085163e+08 | I18: =FSM!K25 -> 6.2444116e+08
B19: % margin | D19: =D18/D14 -> 0.096304076 | E19: =E18/E14 -> 0.10552228 | F19: =F18/F14 -> 0.108045 | G19: =G18/G14 -> 0.10749144 | H19: =H18/H14 -> 0.10686982 | I19: =I18/I14 -> 0.10626308
B21: Tax on EBIT | D21: =D18*D22 -> 64582257 | E21: =E18*E22 -> 83389435 | F21: =F18*F22 -> 1.0078177e+08 | G21: =G18*G22 -> 1.1532982e+08 | H21: =H18*H22 -> 1.2844162e+08 | I21: =I18*I22 -> 1.4049926e+08
B22: Tax rate | D22: =FSM!F40 -> 0.23303957 | E22: =FSM!G40 -> 0.225 | F22: =FSM!H40 -> 0.225 | G22: =FSM!I40 -> 0.225 | H22: =FSM!J40 -> 0.225 | I22: =FSM!K40 -> 0.225
B23: NOPAT (aka EBIAT) | D23: =D18*(1-D22) -> 2.1254774e+08 | E23: =E18*(1-E22) -> 2.8723028e+08 | F23: =F18*(1-F22) -> 3.471372e+08 | G23: =G18*(1-G22) -> 3.9724715e+08 | H23: =H18*(1-H22) -> 4.4241002e+08 | I23: =I18*(1-I22) -> 4.839419e+08
B25: Depreciation & amortization | E25: =FSM!G174 -> 86759301 | F25: =FSM!H174 -> 92694527 | G25: =FSM!I174 -> 1.0988313e+08 | H25: =FSM!J174 -> 1.2690544e+08 | I25: =FSM!K174 -> 1.4359141e+08
B26: Changes in net working capital | E26: =D32-E32 -> 37161990 | F26: =E32-F32 -> 10444965 | G26: =F32-G32 -> 10270804 | H26: =G32-H32 -> 9448899 | I26: =H32-I32 -> 8818762.7
B27: Capital expenditures | E27: =-FSM!G163 -> -35122413 | F27: =-FSM!H163 -> -82913409 | G27: =-FSM!I163 -> -95370753 | H27: =-FSM!J163 -> -1.0683122e+08 | I27: =-FSM!K163 -> -1.175274e+08
B28: Lease Additons | E28: =-FSM!G269 -> -53366788 | F28: =-FSM!H269 -> -62991433 | G28: =-FSM!I269 -> -72455595 | H28: =-FSM!J269 -> -81162403 | I28: =-FSM!K269 -> -89288563
B30: Unlevered free cash flows (UFCF) | E30: =SUM(E23:E28) -> 3.2266237e+08 | F30: =SUM(F23:F28) -> 3.0437185e+08 | G30: =SUM(G23:G28) -> 3.4957474e+08 | H30: =SUM(H23:H28) -> 3.9077073e+08 | I30: =SUM(I23:I28) -> 4.2953611e+08
B32: Net working capital (WC Assets - WC liabilities) | D32: =FSM!F210 -> -20753313 | E32: =FSM!G210 -> -57915303 | F32: =FSM!H210 -> -68360268 | G32: =FSM!I210 -> -78631072 | H32: =FSM!J210 -> -88079971 | I32: =FSM!K210 -> -96898734
B33: as % of revenue | D33: =D32/D14 -> -0.0072118812 | E33: =E32/E14 -> -0.016489557 | F33: =F32/F14 -> -0.016489557 | G33: =G32/G14 -> -0.016489557 | H33: =H32/H14 -> -0.016489557 | I33: =I32/I14 -> -0.016489557
B35: ="Present value of UFCF on "&TEXT(D7,"mmm dd, yyyy")&" valuation date" -> Present value of UFCF on Dec 31, 2025 valuation date
D36: Val date | E36: Yr 1 - Stub | F36: Year 2 | G36: Year 3 | H36: Year 4 | I36: Year 5
B37: Date for discounting cash flows | D37: =D7 -> 46022 | E37: =IF($H$9=1,AVERAGE(E12,D37),E12) -> 46387 | F37: =IF($H$9=1,AVERAGE(F12,E12),F12) -> 46752 | G37: =IF($H$9=1,AVERAGE(G12,F12),G12) -> 47118 | H37: =IF($H$9=1,AVERAGE(H12,G12),H12) -> 47483 | I37: =IF($H$9=1,AVERAGE(I12,H12),I12) -> 47848
B38: Unlevered free cash flows (UFCF) stub adjusted | C38: =D8 -> 1 | E38: =E30*C38 -> 3.2266237e+08 | F38: =F30 -> 3.0437185e+08 | G38: =G30 -> 3.4957474e+08 | H38: =H30 -> 3.9077073e+08 | I38: =I30 -> 4.2953611e+08
B39: Present value of of unlevered free cash flows | E39: =E38/(1+WACC!D$78)^((E37-$D$37)/365) -> 2.5946623e+08 | F39: =F38/(1+WACC!E$78)^((F37-$D$37)/365) -> 1.9682015e+08 | G39: =G38/(1+WACC!F$78)^((G37-$D$37)/365) -> 1.8166794e+08 | H39: =H38/(1+WACC!G$78)^((H37-$D$37)/365) -> 1.6330249e+08 | I39: =I38/(1+WACC!H$78)^((I37-$D$37)/365) -> 1.4434541e+08
B40: Terminal value - growth in perpetuity approach | E40: Terminal value - EBITDA multiple approach
B41: Long term growth rate | C41: 0.1 | E41: Terminal year EBITDA | I41: =I16 -> 7.6803256e+08
B42: =YEAR(I12)&" FCF x (1+g)" -> 2030 FCF x (1+g) | C42: =I38*(1+C41) -> 4.7248972e+08 | E42: EBITDA multiple | I42: 9.2
B43: ="Terminal value in "&YEAR(I12) -> Terminal value in 2030 | C43: =C42/(WACC!H78-C41) -> 3.2911878e+09 | E43: ="Terminal value in "&YEAR(I12) -> Terminal value in 2030 | I43: =I41*I42 -> 7.0658996e+09
B44: Present value of terminal value | C44: =C43/(1+WACC!H78)^((I37-$D$37)/365) -> 1.1060022e+09 | E44: Present value of terminal value | I44: =I43/(1+WACC!H78)^((I37-D37)/365) -> 2.3744923e+09
B45: Present value of stage 1 cash flows | C45: =SUM(E39:I39) -> 9.4560222e+08 | E45: Present value of stage 1 cash flows | I45: =C45 -> 9.4560222e+08
B46: Total enterprise value (TEV) | C46: =SUM(C44:C45) -> 2.0516044e+09 | E46: Enterprise value (stage 1 + 2) | I46: =SUM(I44:I45) -> 3.3200946e+09
B48: Terminal value as % of TEV | C48: =C44/C46 -> 0.53909135 | E48: Terminal value as % of TEV | I48: =I44/I46 -> 0.71518817
...

Sheet WACC
B2: WACC Buildup
B3: =DCF!B3 -> All amounts are shown in EGP, except per-share data, ratios, and shares outstanding
B4: Cost of capital assumptions
B6: Cost of debt | C6: 0.2
B7: Tax rate | C7: 0.225
B8: Cost of debt (after tax) | C8: =C6*(1-C7) -> 0.155
B10: Risk free rate | C10: 0.2313
B11: Beta | C11: =IF(C32="Observed",(2/3)*C34+(1/3),C35) -> 0.29172822
B12: Market risk premium | C12: 0.055
B13: Cost of equity | C13: =C10+C11*(C12) -> 0.24734505
B15: Capital weights (capital structure)
D16: Target
C17: Current | D17: (override) | E17: % of total
B18: Equity | C18: =DCF!I60*DCF!H5 -> 6812000000 | E18: =C18/(C18+C19) -> 0.95265947
B19: Debt | C19: =DCF!C56 -> 338508901 | E19: =C19/(C19+C18) -> 0.047340533
B21: Cost of capital (WACC) | E21: =E18*C13+E19*C8 -> 0.24297339
B23: WACC sensitivity to MRP and Beta
D24: Beta
C25: =E21 -> 0.24297339 | D25: =E25-0.1 -> 0.57909163 | E25: 0.67909163 | F25: =E25+0.1 -> 0.77909163
C26: =C27-0.005 -> 0.045 | D26: 0.25251339 | E26: 0.25680036 | F26: 0.26108732
B27: Market | C27: =C28-0.005 -> 0.05 | D27: 0.25527177 | E27: 0.26003507 | F27: 0.26479837
B28: Risk | C28: 0.055 | D28: 0.25803016 | E28: 0.26326979 | F28: 0.26850941
B29: Premium | C29: =C28+0.005 -> 0.06 | D29: 0.26078854 | E29: 0.2665045 | F29: 0.27222046
C30: =C29+0.005 -> 0.065 | D30: 0.26354693 | E30: 0.26973922 | F30: 0.2759315
B32: Select Beta for model | C32: Industry
B34: Observed | C34: 1.18
B35: Industry beta | C35: =C47 -> 0.29172822
B37: Industry beta
C39: Observed b | D39: Share price | E39: Dil. shares | F39: Market cap | G39: Net Debt | H39: Tax rate | I39: Delev. b
B40: Juhayna (JUFO.CA) | C40: 0.23 | D40: 27.33 | E40: 1176756353 | F40: =E40*D40 -> 3.2160751e+10 | G40: 5522542793 | H40: 0.225 | I40: =C40/(1+(1-H40)*(G40/F40)) -> 0.20298645
B41: Edita (EFID.CA) | C41: 0.26 | D41: 21.33 | E41: 1400027312 | F41: =E41*D41 -> 2.9862583e+10 | G41: 627731652 | H41: 0.225 | I41: =C41/(1+(1-H41)*(G41/F41)) -> 0.25583223
B42: Spinneys (SPINNEYS.AE) | C42: 0.46 | D42: 1.3 | E42: 3600000000 | F42: =E42*D42 -> 4680000000 | G42: 233138000 | H42: 0.09 | I42: =C42/(1+(1-H42)*(G42/F42)) -> 0.44005142
B43: BinDawood (4161.SR) | C43: 0.37 | D43: 4.65 | E43: 1143000000 | F43: =E43*D43 -> 5314950000 | G43: 2674660774 | H43: 0.2 | I43: =C43/(1+(1-H43)*(G43/F43)) -> 0.26379829
B44: Gourmet Egypt | C44: 1.18 | D44: 17.03 | E44: 400000000 | F44: =E44*D44 -> 6812000000 | G44: =DCF!C64 -> 32088119 | H44: 0.225
B46: Industry average delevered beta | C46: =AVERAGE(I40:I43) -> 0.2906671
B47: =FSM!Company_Name&" beta" -> Gourmet Egypt beta | C47: =C46*(1+(1-H44)*(G44/F44)) -> 0.29172822
B49: Year-by-Year Cost of Equity and WACC
B50: Fiscal year | C50: =FSM!F$13 -> 2025 | D50: =FSM!G$13 -> 2026 | E50: =FSM!H$13 -> 2027 | F50: =FSM!I$13 -> 2028 | G50: =FSM!J$13 -> 2029 | H50: =FSM!K$13 -> 2030
B51: Fiscal year end date | C51: =FSM!F$14 -> 46022 | D51: =FSM!G$14 -> 46387 | E51: =FSM!H$14 -> 46752 | F51: =FSM!I$14 -> 47118 | G51: =FSM!J$14 -> 47483 | H51: =FSM!K$14 -> 47848
B53: RELEVERED BETA (D/E changes every year)
...

Sheet Trading Comps
B2: Comparable Companies Analysis (Trading Comps)
B4: Refresh date: | C4: 46274
B6: GENERAL INFORMATION
B7: Ticker | C7: JUFO.CA | D7: EFID.CA | E7: SPINNEYS.AE | F7: 4161.SR | G7: GOUR.CA
B8: Company | C8: Juhayna Food Industries | D8: Edita Food Industries | E8: Spinneys 1961 Holding | F8: BinDawood Holding | G8: Gourmet Egypt.com for Food S.A.E.
B9: Exchange / Currency | C9: EGX / EGP | D9: EGX / EGP | E9: DFM / AED | F9: Tadawul / SAR | G9: EGX / EGP
B10: Fiscal year end | C10: 46387 | D10: 46387 | E10: 46387 | F10: 46387 | G10: 46387
B11: Last closing price | C11: 27.33 | D11: 21.33 | E11: 1.3 | F11: 4.65 | G11: 17.03
B12: Price as of | C12: 46213 | D12: 46213 | E12: 46213 | F12: 46213 | G12: 46274
B14: FULLY DILUTED SHARES
B15: Basic shares outstanding | C15: 1176756353 | D15: 1400027312 | E15: 3600000000 | F15: 1143000000 | G15: =FSM!D10 -> 400000000
B16: Options / RSUs / other dilution | C16: 0 | D16: 0 | E16: 0 | F16: 0 | G16: 0
B17: Fully diluted shares | C17: =SUM(C15:C16) -> 1176756353 | D17: =SUM(D15:D16) -> 1400027312 | E17: =SUM(E15:E16) -> 3600000000 | F17: =SUM(F15:F16) -> 1143000000 | G17: =SUM(G15:G16) -> 400000000
B19: BALANCE SHEET DATA (latest reported)
B20: Total debt (incl. leases) | C20: 7260901976 | D20: 5001054285 | E20: 1035610000 | F20: 2825448637 | G20: =DCF!C56 -> 338508901
B21: Minority interest | C21: 1114421 | D21: 367793335 | E21: -26013000 | F21: 133933747 | G21: =DCF!C59 -> -417023
B22: Cash + liquid investments | C22: 1739473604 | D22: 4741115968 | E22: 776459000 | F22: 284721610 | G22: =DCF!C61+DCF!C63 -> 306003759
B23: Net debt / (net cash) | C23: =SUM(C20:C21)-C22 -> 5522542793 | D23: =SUM(D20:D21)-D22 -> 627731652 | E23: =SUM(E20:E21)-E22 -> 233138000 | F23: =SUM(F20:F21)-F22 -> 2674660774 | G23: =SUM(G20:G21)-G22 -> 32088119
B25: MARKET VALUATION
B26: Market capitalization | C26: =C11*C17 -> 3.2160751e+10 | D26: =D11*D17 -> 2.9862583e+10 | E26: =E11*E17 -> 4680000000 | F26: =F11*F17 -> 5314950000 | G26: =G11*G17 -> 6812000000
B27: Enterprise value (EV) | C27: =C26+C23 -> 3.7683294e+10 | D27: =D26+D23 -> 3.0490314e+10 | E27: =E26+E23 -> 4913138000 | F27: =F26+F23 -> 7989610774 | G27: =G26+G23 -> 6844088119
B29: LTM FINANCIALS
B30: Revenue | C30: 29984446222 | D30: 20915072432 | E30: 3646759000 | F30: 6347958607 | G30: =FSM!F16 -> 2877655973
B31: EBITDA | C31: 4095464106 | D31: 4218459783 | E31: 731009000 | F31: 911892371 | G31: =FSM!F20 -> 361759057
B32: EBIT | C32: 3573292094 | D32: 3740483615 | E32: 426514000 | F32: 395727489 | G32: =FSM!F25 -> 277129999
B33: Net income | C33: 1909608115 | D33: 2749571345 | E33: 341405000 | F33: 269931705 | G33: =FSM!F31 -> 211212632
B34: EBITDA margin | C34: =C31/C30 -> 0.13658628 | D34: =D31/D30 -> 0.20169473 | E34: =E31/E30 -> 0.20045443 | F34: =F31/F30 -> 0.14365128 | G34: =G31/G30 -> 0.1257131
B36: TRADING MULTIPLES
B37: EV / Revenue (LTM) | C37: =C27/C30 -> 1.2567614 | D37: =D27/D30 -> 1.4578154 | E37: =E27/E30 -> 1.3472615 | F37: =F27/F30 -> 1.258611 | G37: =G27/G30 -> 2.3783552
B38: EV / EBITDA (LTM) | C38: =C27/C31 -> 9.2012268 | D38: =D27/D31 -> 7.227831 | E38: =E27/E31 -> 6.7210363 | F38: =F27/F31 -> 8.7615721 | G38: =G27/G31 -> 18.918913
B39: EV / EBIT (LTM) | C39: =C27/C32 -> 10.54582 | D39: =D27/D32 -> 8.1514364 | E39: =E27/E32 -> 11.519289 | F39: =F27/F32 -> 20.189678 | G39: =G27/G32 -> 24.696309
B40: P / E (LTM) | C40: =C26/C33 -> 16.841545 | D40: =D26/D33 -> 10.860814 | E40: =E26/E33 -> 13.708059 | F40: =F26/F33 -> 19.68998 | G40: =G26/G33 -> 32.251859
B42: PEER STATISTICS
C43: EV/Revenue | D43: EV/EBITDA | E43: EV/EBIT | F43: P/E
B44: Mean | C44: =AVERAGE(C37:F37) -> 1.3301123 | D44: =AVERAGE(C38:F38) -> 7.9779165 | E44: =AVERAGE(C39:F39) -> 12.601556 | F44: =AVERAGE(C40:F40) -> 15.2751
B45: Median | C45: =MEDIAN(C37:F37) -> 1.3029363 | D45: =MEDIAN(C38:F38) -> 7.9947015 | E45: =MEDIAN(C39:F39) -> 11.032554 | F45: =MEDIAN(C40:F40) -> 15.274802
B46: High | C46: =MAX(C37:F37) -> 1.4578154 | D46: =MAX(C38:F38) -> 9.2012268 | E46: =MAX(C39:F39) -> 20.189678 | F46: =MAX(C40:F40) -> 19.68998
B47: Low | C47: =MIN(C37:F37) -> 1.2567614 | D47: =MIN(C38:F38) -> 6.7210363 | E47: =MIN(C39:F39) -> 8.1514364 | F47: =MIN(C40:F40) -> 10.860814
B49: IMPLIED VALUATION (from peer MEDIAN multiples)
B50: Via EV/EBITDA:
...
