Workbook
Name Company_Name: FSM!$D$5
Name Company_Name: #REF!
Name Hist_Yr: FSM!#REF!
Name Hist_Yr: #REF!
Name IQ_CH: 110000
Name IQ_CQ: 5000
Name IQ_CY: 10000
Name IQ_DAILY: 500000
Name IQ_FH: 100000
Name IQ_FQ: 500
Name IQ_FY: 1000
Name IQ_LTM: 2000
Name IQ_MONTH: 15000
Name IQ_NTM: 6000
Name IQ_WEEK: 50000
Name IQ_YTD: 3000

Sheet FSM
C2: =Company_Name&" - Financial Statement Model" -> Oriental Weavers - Financial Statement Model
C3: All amounts are shown in EGP, except per-share data, ratios, and shares outstanding
C5: Company Name | D5: Oriental Weavers
C6: Ticker | D6: ORWE.CA
C7: Latest Closing Share Price | D7: 23.48
C8: Latest Closing Share Price Date | D8: 46190
C9: Last Historical Year | D9: 46022
C10: Shares outstanding | D10: 665107268
C12: INCOME STATEMENT
C13: Fiscal year | D13: =E13-1 -> 2023 | E13: =F13-1 -> 2024 | F13: =YEAR(D9) -> 2025 | G13: =F13+1 -> 2026 | H13: =G13+1 -> 2027 | I13: =H13+1 -> 2028 | J13: =I13+1 -> 2029 | K13: =J13+1 -> 2030
C14: Fiscal year end date | D14: =EOMONTH(E14,-12) -> 45291 | E14: =EOMONTH(F14,-12) -> 45657 | F14: =D9 -> 46022 | G14: =EOMONTH(F14,12) -> 46387 | H14: =EOMONTH(G14,12) -> 46752 | I14: =EOMONTH(H14,12) -> 47118 | J14: =EOMONTH(I14,12) -> 47483 | K14: =EOMONTH(J14,12) -> 47848
C16: Net Sales (Revenues) | D16: 17658543016 | E16: 24288877875 | F16: 26622797999 | G16: =G183 -> 28494670000 | H16: =H183 -> 3.0451784e+10 | I16: =I183 -> 3.2500681e+10 | J16: =J183 -> 3.4424825e+10 | K16: =K183 -> 3.6420561e+10
C17: Cost of Sales (COGS) | D17: -15108838958 | E17: -21185701953 | F17: -23272535382 | G17: =G18-G16 -> -2.4908848e+10 | H17: =H18-H16 -> -2.6619675e+10 | I17: =I18-I16 -> -2.8410735e+10 | J17: =J18-J16 -> -3.0092741e+10 | K17: =K18-K16 -> -3.1837329e+10
C18: Gross Profit | D18: =SUM(D16:D17) -> 2549704058 | E18: =SUM(E16:E17) -> 3103175922 | F18: =SUM(F16:F17) -> 3350262617 | G18: =G16*G47 -> 3.5858225e+09 | H18: =H16*H47 -> 3.8321094e+09 | I18: =I16*I47 -> 4.0899464e+09 | J18: =J16*J47 -> 4.3320843e+09 | K18: =K16*K47 -> 4.5832314e+09
C19: Selling & Distribution Expenses | D19: -208574673 | E19: -254754592 | F19: -299019544 | G19: =G$16*G48 -> -3.1849237e+08 | H19: =H$16*H48 -> -3.4036754e+08 | I19: =I$16*I48 -> -3.632686e+08 | J19: =J$16*J48 -> -3.8477526e+08 | K19: =K$16*K48 -> -4.0708212e+08
C20: General & Administrative Expenses | D20: -513145476 | E20: -630066477 | F20: -752483532 | G20: =G$16*G49 -> -7.9086479e+08 | H20: =H$16*H49 -> -8.4518416e+08 | I20: =I$16*I49 -> -9.0205097e+08 | J20: =J$16*J49 -> -9.5545526e+08 | K20: =K$16*K49 -> -1.0108466e+09
C21: Expected Credit Loss (ECL) | D21: -68304458 | E21: -24331700 | F21: -253260437 | G21: =G$16*G50 -> -1.3661055e+08 | H21: =H$16*H50 -> -1.4599344e+08 | I21: =I$16*I50 -> -1.5581637e+08 | J21: =J$16*J50 -> -1.6504119e+08 | K21: =K$16*K50 -> -1.7460924e+08
C22: Formed Provisions & Impairment | D22: -98471317 | E22: -145206693 | F22: -150112954 | G22: =G$16*G51 -> -1.6330527e+08 | H22: =H$16*H51 -> -1.7452165e+08 | I22: =I$16*I51 -> -1.8626405e+08 | J22: =J$16*J51 -> -1.9729148e+08 | K22: =K$16*K51 -> -2.087292e+08
C23: Provision No Longer Required | D23: 0 | E23: 0 | F23: 25647760 | G23: 0 | H23: 0 | I23: 0 | J23: 0 | K23: 0
C24: Reverse of Impairment (Assets Held for Sale) | D24: 252358760 | E24: 0 | F24: 0 | G24: 0 | H24: 0 | I24: 0 | J24: 0 | K24: 0
C25: Gain on Sale of Assets Held for Sale | D25: 34761620 | E25: 0 | F25: 918596 | G25: 0 | H25: 0 | I25: 0 | J25: 0 | K25: 0
C26: Capital Gain | D26: 24368149 | E26: 42177712 | F26: 14593979 | G26: 0 | H26: 0 | I26: 0 | J26: 0 | K26: 0
C27: Other Operating Revenues | D27: 329050807 | E27: 594252959 | F27: 454183569 | G27: =G$16*G52 -> 5.7141394e+08 | H27: =H$16*H52 -> 6.1066066e+08 | I27: =I$16*I52 -> 6.5174794e+08 | J27: =J$16*J52 -> 6.9033349e+08 | K27: =K$16*K52 -> 7.303547e+08
C28: Operating Profit (EBIT) | D28: =SUM(D18:D27) -> 2301747470 | E28: =SUM(E18:E27) -> 2685247131 | F28: =SUM(F18:F27) -> 2390730054 | G28: =SUM(G18:G27) -> 2.7479634e+09 | H28: =SUM(H18:H27) -> 2.9367032e+09 | I28: =SUM(I18:I27) -> 3.1342944e+09 | J28: =SUM(J18:J27) -> 3.3198546e+09 | K28: =SUM(K18:K27) -> 3.512319e+09
C29: Financial Investments Income | D29: 51753278 | E29: 177096014 | F29: 18508874 | G29: 0 | H29: 0 | I29: 0 | J29: 0 | K29: 0
C30: Treasury Bills Returns | D30: 240967663 | E30: 579166115 | F30: 430930850 | G30: 0 | H30: 0 | I30: 0 | J30: 0 | K30: 0
C31: Financial Assets at Amortized Cost Returns | D31: 15012317 | E31: 50722790 | F31: 131952040 | G31: 0 | H31: 0 | I31: 0 | J31: 0 | K31: 0
C32: Interest Income | D32: 101662197 | E32: 216179494 | F32: 253316404 | G32: =G240 -> 2.5613413e+08 | H32: =H240 -> 2.3955147e+08 | I32: =I240 -> 2.4138424e+08 | J32: =J240 -> 2.4624853e+08 | K32: =K240 -> 2.543303e+08
C33: Finance Expenses (Interest Expense) | D33: -459366283 | E33: -552552323 | F33: -535526807 | G33: =G239 -> -6.2702751e+08 | H33: =H239 -> -6.3100094e+08 | I33: =I239 -> -6.3516072e+08 | J33: =J239 -> -6.3906721e+08 | K33: =K239 -> -6.4311905e+08
C34: Foreign Exchange Differences | D34: -166163055 | E34: -351533473 | F34: -51440512 | G34: 0 | H34: 0 | I34: 0 | J34: 0 | K34: 0
C35: Net Profit Before Income Tax (EBT) | D35: =SUM(D28:D34) -> 2085613587 | E35: =SUM(E28:E34) -> 2804325748 | F35: =SUM(F28:F34) -> 2638470903 | G35: =SUM(G28:G34) -> 2.3770701e+09 | H35: =SUM(H28:H34) -> 2.5452538e+09 | I35: =SUM(I28:I34) -> 2.7405179e+09 | J35: =SUM(J28:J34) -> 2.9270359e+09 | K35: =SUM(K28:K34) -> 3.1235302e+09
C36: Current Income Tax | D36: -234454961 | E36: -426367543 | F36: -343889121 | G36: =G35*G53 -> -2.6041036e+08 | H36: =H35*H53 -> -2.7883505e+08 | I36: =I35*I53 -> -3.0022643e+08 | J36: =J35*J53 -> -3.2065966e+08 | K36: =K35*K53 -> -3.421858e+08
C37: Deferred Tax | D37: 40823397 | E37: 163723612 | F37: -31181909 | G37: 0 | H37: 0 | I37: 0 | J37: 0 | K37: 0
C38: Net Profit for the Year | D38: =SUM(D35:D37) -> 1891982023 | E38: =SUM(E35:E37) -> 2541681817 | F38: =SUM(F35:F37) -> 2263399873 | G38: =SUM(G35:G37) -> 2.1166597e+09 | H38: =SUM(H35:H37) -> 2.2664187e+09 | I38: =SUM(I35:I37) -> 2.4402915e+09 | J38: =SUM(J35:J37) -> 2.6063763e+09 | K38: =SUM(K35:K37) -> 2.7813444e+09
C39: Parent Company Shareholders | D39: =D38-D40 -> 1740203598 | E39: =E38-E40 -> 2192283305 | F39: =F38-F40 -> 2189343558 | G39: =G38-G40 -> 2.0474046e+09 | H39: =H38-H40 -> 2.1922636e+09 | I39: =I38-I40 -> 2.3604475e+09 | J39: =J38-J40 -> 2.5210981e+09 | K39: =K38-K40 -> 2.6903414e+09
C40: Non-controlling Interest | D40: 151778425 | E40: 349398512 | F40: 74056315 | G40: =G255 -> 69255115 | H40: =H255 -> 74155089 | I40: =I255 -> 79844042 | J40: =J255 -> 85278180 | K40: =K255 -> 91002974
C42: EBITDA | D42: =D28+D164 -> 3202947781 | E42: =E28+E164 -> 3981039203 | F42: =F28+F164 -> 3667611139 | G42: =G28+G164 -> 4.1159835e+09 | H42: =H28+H164 -> 4.3986837e+09 | I42: =I28+I164 -> 4.6946418e+09 | J42: =J28+J164 -> 4.9725796e+09 | K42: =K28+K164 -> 5.2608586e+09
C43: EBITDA margin % | D43: =D42/D16 -> 0.18138234 | E43: =E42/E16 -> 0.16390379 | F43: =F42/F16 -> 0.13776205 | G43: =G42/G16 -> 0.14444749 | H43: =H42/H16 -> 0.14444749 | I43: =I42/I16 -> 0.14444749 | J43: =J42/J16 -> 0.14444749 | K43: =K42/K16 -> 0.14444749
C45: Growth Rates & Margins
C46: Revenue growth | D46: =(D16/13255653997)-1 -> 0.33215178 | E46: =E16/D16-1 -> 0.37547463 | F46: =F16/E16-1 -> 0.096090076 | G46: =G16/F16-1 -> 0.070310867 | H46: =H16/G16-1 -> 0.068683517 | I46: =I16/H16-1 -> 0.067283326 | J46: =J16/I16-1 -> 0.059203183 | K46: =K16/J16-1 -> 0.057973733
...

Sheet DCF
B2: Discounted Cash Flow Valuation
B3: =FSM!C3 -> All amounts are shown in EGP, except per-share data, ratios, and shares outstanding
B4: Most recent fiscal year end | D4: 46022 | F4: Discount rate (WACC) | H4: =+WACC!E21 -> 0.19536055 | I4: Link from WACC
B5: End of first fiscal year | D5: =EOMONTH(D4,12) -> 46387 | F5: Share price (Public Co) | H5: 23.48
B6: Most recent quarter end date | D6: 46022 | F6: Share price date | H6: 46188
B7: Valuation date | D7: 46190 | F7: Implied Share Price | H7: =C73 -> 29.428047
B8: Portion of First Year Cash Flows | D8: =YEARFRAC(D7,D5) -> 0.53888889 | F8: Upside / (Downside) | H8: =H7/H5-1 -> 0.25332397
F9: Midyear adjustment? | H9: 1
B10: Unlevered Free Cash Flows
C11: LTM | D11: Actual | E11: Forecasts
B12: Fiscal year ended | C12: =D7 -> 46190 | D12: =D4 -> 46022 | E12: =EOMONTH(D12,12) -> 46387 | F12: =EOMONTH(E12,12) -> 46752 | G12: =EOMONTH(F12,12) -> 47118 | H12: =EOMONTH(G12,12) -> 47483 | I12: =EOMONTH(H12,12) -> 47848
B14: Revenue | C14: =E14*(1-$D$8)+D14*$D$8 -> 2.7485939e+10 | D14: =FSM!F16 -> 26622797999 | E14: =FSM!G16 -> 28494670000 | F14: =FSM!H16 -> 3.0451784e+10 | G14: =FSM!I16 -> 3.2500681e+10 | H14: =FSM!J16 -> 3.4424825e+10 | I14: =FSM!K16 -> 3.6420561e+10
B15: % growth | E15: =E14/D14-1 -> 0.070310867 | F15: =F14/E14-1 -> 0.068683517 | G15: =G14/F14-1 -> 0.067283326 | H15: =H14/G14-1 -> 0.059203183 | I15: =I14/H14-1 -> 0.057973733
B16: EBITDA | C16: =E16*(1-$D$8)+D16*$D$8 -> 3.8743606e+09 | D16: =FSM!F42 -> 3667611139 | E16: =FSM!G42 -> 4.1159835e+09 | F16: =FSM!H42 -> 4.3986837e+09 | G16: =FSM!I42 -> 4.6946418e+09 | H16: =FSM!J42 -> 4.9725796e+09 | I16: =FSM!K42 -> 5.2608586e+09
B17: % margin | D17: =D16/D14 -> 0.13776205 | E17: =E16/E14 -> 0.14444749 | F17: =F16/F14 -> 0.14444749 | G17: =G16/G14 -> 0.14444749 | H17: =H16/H14 -> 0.14444749 | I17: =I16/I14 -> 0.14444749
B18: EBIT | C18: =E18*(1-$D$8)+D18*$D$8 -> 2.5554543e+09 | D18: =FSM!F28 -> 2390730054 | E18: =FSM!G28 -> 2.7479634e+09 | F18: =FSM!H28 -> 2.9367032e+09 | G18: =FSM!I28 -> 3.1342944e+09 | H18: =FSM!J28 -> 3.3198546e+09 | I18: =FSM!K28 -> 3.512319e+09
B19: % margin | D19: =D18/D14 -> 0.089800105 | E19: =E18/E14 -> 0.096437806 | F19: =F18/F14 -> 0.096437806 | G19: =G18/G14 -> 0.096437806 | H19: =H18/H14 -> 0.096437806 | I19: =I18/I14 -> 0.096437806
B21: Tax on EBIT | D21: =D18*D22 -> 3.398535e+08 | E21: =E18*E22 -> 3.0104209e+08 | F21: =F18*F22 -> 3.2171872e+08 | G21: =G18*G22 -> 3.4336503e+08 | H21: =H18*H22 -> 3.6369333e+08 | I21: =I18*I22 -> 3.8477799e+08
B22: Tax rate | D22: =-FSM!F53 -> 0.1421547 | E22: =-FSM!G53 -> 0.10955098 | F22: =-FSM!H53 -> 0.10955098 | G22: =-FSM!I53 -> 0.10955098 | H22: =-FSM!J53 -> 0.10955098 | I22: =-FSM!K53 -> 0.10955098
B23: NOPAT (aka EBIAT) | D23: =D18*(1-D22) -> 2.0508765e+09 | E23: =E18*(1-E22) -> 2.4469214e+09 | F23: =F18*(1-F22) -> 2.6149845e+09 | G23: =G18*(1-G22) -> 2.7909294e+09 | H23: =H18*(1-H22) -> 2.9561613e+09 | I23: =I18*(1-I22) -> 3.127541e+09
B25: Depreciation & amortization | E25: =FSM!G164 -> 1.3680201e+09 | F25: =FSM!H164 -> 1.4619805e+09 | G25: =FSM!I164 -> 1.5603474e+09 | H25: =FSM!J164 -> 1.6527249e+09 | I25: =FSM!K164 -> 1.7485396e+09
B26: Changes in net working capital | E26: =D32-E32 -> -1.737846e+09 | F26: =E32-F32 -> -9.06011e+08 | G26: =F32-G32 -> -9.4850037e+08 | H26: =G32-H32 -> -8.9074796e+08 | I26: =H32-I32 -> -9.2389012e+08
B27: Capital expenditures | E27: =-FSM!G153 -> -1.0429717e+09 | F27: =-FSM!H153 -> -1.1146067e+09 | G27: =-FSM!I153 -> -1.1896012e+09 | H27: =-FSM!J153 -> -1.2600293e+09 | I27: =-FSM!K153 -> -1.3330779e+09
B28: as % of revenue | E28: =E27/E14 -> -0.036602345 | F28: =F27/F14 -> -0.036602345 | G28: =G27/G14 -> -0.036602345 | H28: =H27/H14 -> -0.036602345 | I28: =I27/I14 -> -0.036602345
B30: Unlevered free cash flows (UFCF) | E30: =E23+E25+E26+E27 -> 1.0341237e+09 | F30: =F23+F25+F26+F27 -> 2.0563473e+09 | G30: =G23+G25+G26+G27 -> 2.2131753e+09 | H30: =H23+H25+H26+H27 -> 2.4581089e+09 | I30: =I23+I25+I26+I27 -> 2.6191125e+09
B32: Net working capital (WC Assets - WC liabilities) | D32: =FSM!F215 -> 11453251931 | E32: =FSM!G215 -> 1.3191098e+10 | F32: =FSM!H215 -> 1.4097109e+10 | G32: =FSM!I215 -> 1.5045609e+10 | H32: =FSM!J215 -> 1.5936357e+10 | I32: =FSM!K215 -> 1.6860247e+10
B33: as % of revenue | D33: =D32/D14 -> 0.43020467 | E33: =E32/E14 -> 0.46293212 | F33: =F32/F14 -> 0.46293212 | G33: =G32/G14 -> 0.46293212 | H33: =H32/H14 -> 0.46293212 | I33: =I32/I14 -> 0.46293212
B35: ="Present value of UFCF on "&TEXT(D7,"mmm dd, yyyy")&" valuation date" -> Present value of UFCF on Jun 17, 2026 valuation date
D36: Val date | E36: Yr 1 - Stub | F36: Year 2 | G36: Year 3 | H36: Year 4 | I36: Year 5
B37: Date for discounting cash flows | D37: =D7 -> 46190 | E37: =IF($H$9=1,AVERAGE(E12,D37),E12) -> 46288.5 | F37: =IF($H$9=1,AVERAGE(F12,E12),F12) -> 46569.5 | G37: =IF($H$9=1,AVERAGE(G12,F12),G12) -> 46935 | H37: =IF($H$9=1,AVERAGE(H12,G12),H12) -> 47300.5 | I37: =IF($H$9=1,AVERAGE(I12,H12),I12) -> 47665.5
B38: Unlevered free cash flows (UFCF) stub adjusted | C38: =D8 -> 0.53888889 | E38: =E30*C38 -> 5.5727779e+08 | F38: =F30 -> 2.0563473e+09 | G38: =G30 -> 2.2131753e+09 | H38: =H30 -> 2.4581089e+09 | I38: =I30 -> 2.6191125e+09
B39: Present value of of unlevered free cash flows | E39: =E38/(1+$H$4)^((E37-$D$37)/365) -> 5.3107718e+08 | F39: =F38/(1+$H$4)^((F37-$D$37)/365) -> 1.7081218e+09 | G39: =G38/(1+$H$4)^((G37-$D$37)/365) -> 1.5375636e+09 | H39: =H38/(1+$H$4)^((H37-$D$37)/365) -> 1.4282799e+09 | I39: =I38/(1+$H$4)^((I37-$D$37)/365) -> 1.2731144e+09
B41: Terminal value - growth in perpetuity approach | E41: Terminal value - EBITDA multiple approach
B42: Long term growth rate | C42: 0.1 | E42: Terminal year EBITDA | I42: =I16 -> 5.2608586e+09
B43: =YEAR(I12)&" FCF x (1+g)" -> 2030 FCF x (1+g) | C43: =I38*(1+C42) -> 2.8810238e+09 | E43: EBITDA multiple | I43: 5.9
B44: ="Terminal value in "&YEAR(I12) -> Terminal value in 2030 | C44: =C43/(H4-C42) -> 3.0211904e+10 | E44: ="Terminal value in "&YEAR(I12) -> Terminal value in 2030 | I44: =I42*I43 -> 3.1039065e+10
B45: Present value of terminal value | C45: =C44/(1+H4)^((I37-$D$37)/365) -> 1.4685589e+10 | E45: Present value of terminal value | I45: =I44/(1+H4)^((I37-D37)/365) -> 1.5087661e+10
B46: Present value of stage 1 cash flows | C46: =SUM(E39:I39) -> 6.4781568e+09 | E46: Present value of stage 1 cash flows | I46: =C46 -> 6.4781568e+09
B47: Total enterprise value (TEV) | C47: =C45+C46 -> 2.1163746e+10 | E47: Enterprise value (stage 1 + 2) | I47: =I45+I46 -> 2.1565818e+10
B49: Terminal value as % of TEV | C49: =C45/C47 -> 0.69390311 | E49: Terminal value as % of TEV | I49: =I45/I47 -> 0.69960996
...

Sheet WACC
B2: WACC Buildup
B3: =DCF!B3 -> All amounts are shown in EGP, except per-share data, ratios, and shares outstanding
B4: Cost of capital assumptions
B6: Cost of debt | C6: =C10+2% -> 0.215826
B7: Tax rate | C7: 0.225
B8: Cost of debt (after tax) | C8: =C6*(1-C7) -> 0.16726515
B10: Risk free rate | C10: 0.195826
B11: Beta | C11: =(2/3*-0.04)+1/3 -> 0.30666667
B12: Market risk premium | C12: =13.94%-9.71% -> 0.0423
B13: Cost of equity | C13: =C10+C11*C12 -> 0.208798
B15: Capital weights (capital structure)
D16: Target
C17: Current | D17: (override) | E17: % of total
B18: Equity | C18: =DCF!H5*DCF!I61 -> 1.5616719e+10 | E18: =C18/(C18+C19) -> 0.67646213
B19: Debt | C19: =DCF!C57 -> 7469154055 | E19: =C19/(C18+C19) -> 0.32353787
B21: Cost of capital (WACC) | E21: =C13*E18+C8*E19 -> 0.19536055
